<?xml version="1.0" ?>
<!-- =================================================================================== -->
<!-- |    This document was autogenerated by xacro from urdf/quadruped.urdf.xacro      | -->
<!-- |    EDITING THIS FILE BY HAND IS NOT RECOMMENDED                                 | -->
<!-- =================================================================================== -->
<robot name="quadruped">
  <material name="black">
    <color rgba="0.0 0.0 0.0 1.0"/>
  </material>
  <material name="blue">
    <color rgba="0.0 0.0 0.8 1.0"/>
  </material>
  <material name="green">
    <color rgba="0.0 0.8 0.0 1.0"/>
  </material>
  <material name="grey">
    <color rgba="0.2 0.2 0.2 1.0"/>
  </material>
  <material name="silver">
    <color rgba="0.9137254901960784 0.9137254901960784 0.8470588235294118 1.0"/>
  </material>
  <material name="orange">
    <color rgba="1.0 0.4235294117647059 0.0392156862745098 1.0"/>
  </material>
  <material name="brown">
    <color rgba="0.8705882352941177 0.8117647058823529 0.7647058823529411 1.0"/>
  </material>
  <material name="white_gray">
    <color rgba="0.8235294117647058 0.8235294117647058 0.8235294117647058 1.0"/>
  </material>
  <material name="gold">
    <color rgba="0.8117647058823529 0.6784313725490196 0.30196078431372547 1.0"/>
  </material>
  <material name="white_blue">
    <color rgba="0.4627450980392157 0.8 0.9921568627450981 1.0"/>
  </material>
  <material name="white_black">
    <color rgba="0.49411764705882355 0.49411764705882355 0.49411764705882355 1.0"/>
  </material>
  <material name="red">
    <color rgba="0.8 0.0 0.0 1.0"/>
  </material>
  <material name="white">
    <color rgba="1.0 1.0 1.0 1.0"/>
  </material>
  <!-- kinematic value -->
  <!-- <xacro:property name="thigh_ixx" value="0.001983"/>
    <xacro:property name="thigh_ixy" value="0.000245"/>
    <xacro:property name="thigh_ixz" value="0.000013"/>
    <xacro:property name="thigh_iyy" value="0.002103"/>
    <xacro:property name="thigh_iyz" value="0.0000015"/>
    <xacro:property name="thigh_izz" value="0.000408"/> -->
  <!-- <xacro:property name="calf_ixx" value="0.000245"/>
    <xacro:property name="calf_ixy" value="0.0"/>
    <xacro:property name="calf_ixz" value="0.000248"/>
    <xacro:property name="calf_iyy" value="0.000560"/>
    <xacro:property name="calf_iyz" value="0.0"/>
    <xacro:property name="calf_izz" value="0.000006"/> -->
  <link name="root"/>
  <joint name="root_dummy_joint" type="fixed">
    <origin rpy="0 0 0" xyz="0 0 0"/>
    <parent link="root"/>
    <child link="base_link"/>
  </joint>
  <link name="base_link">
    <visual>
      <origin rpy="0 0 0" xyz="0 0 0"/>
      <geometry>
        <mesh filename="package://quadruped_description/meshes/mini_cheetah_base.obj" scale="1 1 1"/>
      </geometry>
      <material name="green"/>
    </visual>
    <collision>
      <origin rpy="0 0 0" xyz="0 0 0"/>
      <geometry>
        <box size="0.3 0.19 0.093"/>
      </geometry>
    </collision>
    <inertial>
      <origin rpy="0 0 0" xyz="0.0 0.0 0.0"/>
      <mass value="3.3"/>
      <inertia ixx="0.011253" ixy="0" ixz="0.0" iyy="0.036203" iyz="0.0" izz="0.042673"/>
    </inertial>
  </link>
  <joint name="FR_hip_joint" type="revolute">
    <origin rpy="0 0 0" xyz="0.19 -0.049 0"/>
    <parent link="base_link"/>
    <child link="FR_hip_link"/>
    <axis xyz="1 0 0"/>
    <dynamics damping="0" friction="0"/>
    <limit effort="20" lower="-1.0471975511965976" upper="0.5235987755982988" velocity="10.6"/>
    <!-- <safety_controller k_velocity="10" k_position="15" soft_lower_limit="-2.0" soft_upper_limit="0.5" /> -->
  </joint>
  <link name="FR_hip_link">
    <visual>
      <origin rpy="3.141592653589793 0 1.5707963267948966" xyz="-0.055 0 0"/>
      <geometry>
        <mesh filename="package://quadruped_description/meshes/mini_cheetah_hip.obj" scale="1 1 1"/>
      </geometry>
      <material name="gold"/>
    </visual>
    <collision>
      <origin rpy="0 -1.5707963267948966 0" xyz="0 0 0"/>
      <geometry>
        <cylinder length="0.09" radius="0.0465"/>
      </geometry>
    </collision>
    <inertial>
      <origin rpy="0 0 0" xyz="0.0 -0.036 0.0"/>
      <mass value="0.54"/>
      <inertia ixx="0.000381" ixy="-5.8e-05" ixz="4.5e-07" iyy="0.00056" iyz="-9.5e-07" izz="0.000444"/>
    </inertial>
  </link>
  <joint name="FR_thigh_joint" type="revolute">
    <origin rpy="0 0 0" xyz="0 -0.062 0"/>
    <parent link="FR_hip_link"/>
    <child link="FR_thigh_link"/>
    <axis xyz="0 -1 0"/>
    <dynamics damping="0" friction="0"/>
    <limit effort="20" lower="-2.2689280275926285" upper="2.2689280275926285" velocity="10.6"/>
    <!-- <safety_controller k_velocity="10" k_position="15" soft_lower_limit="-2.0" soft_upper_limit="0.5" /> -->
  </joint>
  <link name="FR_thigh_link">
    <visual>
      <origin rpy="0 -1.5707963267948966 0" xyz="0 0 0"/>
      <geometry>
        <mesh filename="package://quadruped_description/meshes/mini_cheetah_thigh.obj" scale="1 1 1"/>
      </geometry>
      <material name="white_blue"/>
    </visual>
    <collision>
      <origin rpy="0 0 0" xyz="0 0 -0.11"/>
      <geometry>
        <box size="0.043 0.034 0.22"/>
      </geometry>
    </collision>
    <inertial>
      <origin rpy="0 0 0" xyz="0.0 -0.016 -0.02"/>
      <mass value="0.634"/>
      <inertia ixx="0.0026182086666666662" ixy="-0.0" ixz="0.0" iyy="0.0026548221666666664" iyz="-0.0" izz="0.00015876416666666665"/>
    </inertial>
  </link>
  <joint name="FR_calf_joint" type="revolute">
    <origin rpy="0 0 0" xyz="0 0 -0.209"/>
    <parent link="FR_thigh_link"/>
    <child link="FR_calf_link"/>
    <axis xyz="0 -1 0"/>
    <dynamics damping="0" friction="0"/>
    <limit effort="20" lower="-2.9670597283903604" upper="2.9670597283903604" velocity="10.6"/>
    <!-- <safety_controller k_velocity="10" k_position="15" soft_lower_limit="-2.0" soft_upper_limit="0.5" /> -->
  </joint>
  <link name="FR_calf_link">
    <visual>
      <origin rpy="0 3.141592653589793 0" xyz="0 0 0"/>
      <geometry>
        <mesh filename="package://quadruped_description/meshes/mini_cheetah_calf.obj" scale="1 1 1"/>
      </geometry>
      <material name="white_blue"/>
    </visual>
    <collision>
      <origin rpy="0 0 0" xyz="0 0 -0.1"/>
      <geometry>
        <box size="0.016 0.016 0.2"/>
      </geometry>
    </collision>
    <inertial>
      <origin rpy="0 0 0" xyz="0.0 0.0 0.0"/>
      <mass value="0.064"/>
      <inertia ixx="0.0002146986666666667" ixy="0.0" ixz="0.0" iyy="0.0002146986666666667" iyz="0.0" izz="2.7306666666666666e-06"/>
    </inertial>
  </link>
  <joint name="FR_foot_fixed" type="fixed">
    <origin rpy="0 0 0" xyz="0 0 -0.18"/>
    <parent link="FR_calf_link"/>
    <child link="FR_foot_link"/>
  </joint>
  <link name="FR_foot_link">
    <visual>
      <origin rpy="0 0 0" xyz="0 0.0 0.0"/>
      <geometry>
        <sphere radius="0.025"/>
      </geometry>
      <material name="white_black"/>
    </visual>
    <collision>
      <origin rpy="0 0 0" xyz="0 0 0.0"/>
      <geometry>
        <sphere radius="0.025"/>
      </geometry>
    </collision>
    <inertial>
      <origin rpy="0 0 0" xyz="0.0 0.0 0"/>
      <mass value="0.15"/>
      <inertia ixx="4.2134999999999996e-05" ixy="0" ixz="0" iyy="4.2134999999999996e-05" iyz="0" izz="4.2134999999999996e-05"/>
    </inertial>
  </link>
  <joint name="FL_hip_joint" type="revolute">
    <origin rpy="0 0 0" xyz="0.19 0.049 0"/>
    <parent link="base_link"/>
    <child link="FL_hip_link"/>
    <axis xyz="1 0 0"/>
    <dynamics damping="0" friction="0"/>
    <limit effort="20" lower="-0.5235987755982988" upper="1.0471975511965976" velocity="10.6"/>
    <!-- <safety_controller k_velocity="10" k_position="15" soft_lower_limit="-2.0" soft_upper_limit="0.5" /> -->
  </joint>
  <link name="FL_hip_link">
    <visual>
      <origin rpy="0 0 -1.5707963267948966" xyz="-0.055 0 0"/>
      <geometry>
        <mesh filename="package://quadruped_description/meshes/mini_cheetah_hip.obj" scale="1 1 1"/>
      </geometry>
      <material name="gold"/>
    </visual>
    <collision>
      <origin rpy="0 -1.5707963267948966 0" xyz="0 0 0"/>
      <geometry>
        <cylinder length="0.09" radius="0.0465"/>
      </geometry>
    </collision>
    <inertial>
      <origin rpy="0 0 0" xyz="0.0 0.036 0.0"/>
      <mass value="0.54"/>
      <inertia ixx="0.000381" ixy="5.8e-05" ixz="4.5e-07" iyy="0.00056" iyz="9.5e-07" izz="0.000444"/>
    </inertial>
  </link>
  <joint name="FL_thigh_joint" type="revolute">
    <origin rpy="0 0 0" xyz="0 0.062 0"/>
    <parent link="FL_hip_link"/>
    <child link="FL_thigh_link"/>
    <axis xyz="0 -1 0"/>
    <dynamics damping="0" friction="0"/>
    <limit effort="20" lower="-2.2689280275926285" upper="2.2689280275926285" velocity="10.6"/>
    <!-- <safety_controller k_velocity="10" k_position="15" soft_lower_limit="-2.0" soft_upper_limit="0.5" /> -->
  </joint>
  <link name="FL_thigh_link">
    <visual>
      <origin rpy="0 -1.5707963267948966 0" xyz="0 0 0"/>
      <geometry>
        <mesh filename="package://quadruped_description/meshes/mini_cheetah_thigh.obj" scale="1 1 1"/>
      </geometry>
      <material name="white_blue"/>
    </visual>
    <collision>
      <origin rpy="0 0 0" xyz="0 0 -0.11"/>
      <geometry>
        <box size="0.043 0.034 0.22"/>
      </geometry>
    </collision>
    <inertial>
      <origin rpy="0 0 0" xyz="0.0 0.016 -0.02"/>
      <mass value="0.634"/>
      <inertia ixx="0.0026182086666666662" ixy="0.0" ixz="0.0" iyy="0.0026548221666666664" iyz="0.0" izz="0.00015876416666666665"/>
    </inertial>
  </link>
  <joint name="FL_calf_joint" type="revolute">
    <origin rpy="0 0 0" xyz="0 0 -0.209"/>
    <parent link="FL_thigh_link"/>
    <child link="FL_calf_link"/>
    <axis xyz="0 -1 0"/>
    <dynamics damping="0" friction="0"/>
    <limit effort="20" lower="-2.9670597283903604" upper="2.9670597283903604" velocity="10.6"/>
    <!-- <safety_controller k_velocity="10" k_position="15" soft_lower_limit="-2.0" soft_upper_limit="0.5" /> -->
  </joint>
  <link name="FL_calf_link">
    <visual>
      <origin rpy="0 3.141592653589793 0" xyz="0 0 0"/>
      <geometry>
        <mesh filename="package://quadruped_description/meshes/mini_cheetah_calf.obj" scale="1 1 1"/>
      </geometry>
      <material name="white_blue"/>
    </visual>
    <collision>
      <origin rpy="0 0 0" xyz="0 0 -0.1"/>
      <geometry>
        <box size="0.016 0.016 0.2"/>
      </geometry>
    </collision>
    <inertial>
      <origin rpy="0 0 0" xyz="0.0 0.0 0.0"/>
      <mass value="0.064"/>
      <inertia ixx="0.0002146986666666667" ixy="0.0" ixz="0.0" iyy="0.0002146986666666667" iyz="0.0" izz="2.7306666666666666e-06"/>
    </inertial>
  </link>
  <joint name="FL_foot_fixed" type="fixed">
    <origin rpy="0 0 0" xyz="0 0 -0.18"/>
    <parent link="FL_calf_link"/>
    <child link="FL_foot_link"/>
  </joint>
  <link name="FL_foot_link">
    <visual>
      <origin rpy="0 0 0" xyz="0 0.0 0.0"/>
      <geometry>
        <sphere radius="0.025"/>
      </geometry>
      <material name="white_black"/>
    </visual>
    <collision>
      <origin rpy="0 0 0" xyz="0 0 0.0"/>
      <geometry>
        <sphere radius="0.025"/>
      </geometry>
    </collision>
    <inertial>
      <origin rpy="0 0 0" xyz="0.0 0.0 0"/>
      <mass value="0.15"/>
      <inertia ixx="4.2134999999999996e-05" ixy="0" ixz="0" iyy="4.2134999999999996e-05" iyz="0" izz="4.2134999999999996e-05"/>
    </inertial>
  </link>
  <joint name="RR_hip_joint" type="revolute">
    <origin rpy="0 0 0" xyz="-0.19 -0.049 0"/>
    <parent link="base_link"/>
    <child link="RR_hip_link"/>
    <axis xyz="1 0 0"/>
    <dynamics damping="0" friction="0"/>
    <limit effort="20" lower="-1.0471975511965976" upper="0.5235987755982988" velocity="10.6"/>
    <!-- <safety_controller k_velocity="10" k_position="15" soft_lower_limit="-2.0" soft_upper_limit="0.5" /> -->
  </joint>
  <link name="RR_hip_link">
    <visual>
      <origin rpy="0 0 1.5707963267948966" xyz="0.055 0 0"/>
      <geometry>
        <mesh filename="package://quadruped_description/meshes/mini_cheetah_hip.obj" scale="1 1 1"/>
      </geometry>
      <material name="gold"/>
    </visual>
    <collision>
      <origin rpy="0 -1.5707963267948966 0" xyz="0 0 0"/>
      <geometry>
        <cylinder length="0.09" radius="0.0465"/>
      </geometry>
    </collision>
    <inertial>
      <origin rpy="0 0 0" xyz="-0.0 -0.036 0.0"/>
      <mass value="0.54"/>
      <inertia ixx="0.000381" ixy="5.8e-05" ixz="-4.5e-07" iyy="0.00056" iyz="-9.5e-07" izz="0.000444"/>
    </inertial>
  </link>
  <joint name="RR_thigh_joint" type="revolute">
    <origin rpy="0 0 0" xyz="0 -0.062 0"/>
    <parent link="RR_hip_link"/>
    <child link="RR_thigh_link"/>
    <axis xyz="0 -1 0"/>
    <dynamics damping="0" friction="0"/>
    <limit effort="20" lower="-2.2689280275926285" upper="2.2689280275926285" velocity="10.6"/>
    <!-- <safety_controller k_velocity="10" k_position="15" soft_lower_limit="-2.0" soft_upper_limit="0.5" /> -->
  </joint>
  <link name="RR_thigh_link">
    <visual>
      <origin rpy="0 -1.5707963267948966 0" xyz="0 0 0"/>
      <geometry>
        <mesh filename="package://quadruped_description/meshes/mini_cheetah_thigh.obj" scale="1 1 1"/>
      </geometry>
      <material name="white_blue"/>
    </visual>
    <collision>
      <origin rpy="0 0 0" xyz="0 0 -0.11"/>
      <geometry>
        <box size="0.043 0.034 0.22"/>
      </geometry>
    </collision>
    <inertial>
      <origin rpy="0 0 0" xyz="0.0 -0.016 -0.02"/>
      <mass value="0.634"/>
      <inertia ixx="0.0026182086666666662" ixy="-0.0" ixz="0.0" iyy="0.0026548221666666664" iyz="-0.0" izz="0.00015876416666666665"/>
    </inertial>
  </link>
  <joint name="RR_calf_joint" type="revolute">
    <origin rpy="0 0 0" xyz="0 0 -0.209"/>
    <parent link="RR_thigh_link"/>
    <child link="RR_calf_link"/>
    <axis xyz="0 -1 0"/>
    <dynamics damping="0" friction="0"/>
    <limit effort="20" lower="-2.9670597283903604" upper="2.9670597283903604" velocity="10.6"/>
    <!-- <safety_controller k_velocity="10" k_position="15" soft_lower_limit="-2.0" soft_upper_limit="0.5" /> -->
  </joint>
  <link name="RR_calf_link">
    <visual>
      <origin rpy="0 3.141592653589793 0" xyz="0 0 0"/>
      <geometry>
        <mesh filename="package://quadruped_description/meshes/mini_cheetah_calf.obj" scale="1 1 1"/>
      </geometry>
      <material name="white_blue"/>
    </visual>
    <collision>
      <origin rpy="0 0 0" xyz="0 0 -0.1"/>
      <geometry>
        <box size="0.016 0.016 0.2"/>
      </geometry>
    </collision>
    <inertial>
      <origin rpy="0 0 0" xyz="0.0 0.0 0.0"/>
      <mass value="0.064"/>
      <inertia ixx="0.0002146986666666667" ixy="0.0" ixz="0.0" iyy="0.0002146986666666667" iyz="0.0" izz="2.7306666666666666e-06"/>
    </inertial>
  </link>
  <joint name="RR_foot_fixed" type="fixed">
    <origin rpy="0 0 0" xyz="0 0 -0.18"/>
    <parent link="RR_calf_link"/>
    <child link="RR_foot_link"/>
  </joint>
  <link name="RR_foot_link">
    <visual>
      <origin rpy="0 0 0" xyz="0 0.0 0.0"/>
      <geometry>
        <sphere radius="0.025"/>
      </geometry>
      <material name="white_black"/>
    </visual>
    <collision>
      <origin rpy="0 0 0" xyz="0 0 0.0"/>
      <geometry>
        <sphere radius="0.025"/>
      </geometry>
    </collision>
    <inertial>
      <origin rpy="0 0 0" xyz="0.0 0.0 0"/>
      <mass value="0.15"/>
      <inertia ixx="4.2134999999999996e-05" ixy="0" ixz="0" iyy="4.2134999999999996e-05" iyz="0" izz="4.2134999999999996e-05"/>
    </inertial>
  </link>
  <joint name="RL_hip_joint" type="revolute">
    <origin rpy="0 0 0" xyz="-0.19 0.049 0"/>
    <parent link="base_link"/>
    <child link="RL_hip_link"/>
    <axis xyz="1 0 0"/>
    <dynamics damping="0" friction="0"/>
    <limit effort="20" lower="-0.5235987755982988" upper="1.0471975511965976" velocity="10.6"/>
    <!-- <safety_controller k_velocity="10" k_position="15" soft_lower_limit="-2.0" soft_upper_limit="0.5" /> -->
  </joint>
  <link name="RL_hip_link">
    <visual>
      <origin rpy="3.141592653589793 0 -1.5707963267948966" xyz="0.055 0 0"/>
      <geometry>
        <mesh filename="package://quadruped_description/meshes/mini_cheetah_hip.obj" scale="1 1 1"/>
      </geometry>
      <material name="gold"/>
    </visual>
    <collision>
      <origin rpy="0 -1.5707963267948966 0" xyz="0 0 0"/>
      <geometry>
        <cylinder length="0.09" radius="0.0465"/>
      </geometry>
    </collision>
    <inertial>
      <origin rpy="0 0 0" xyz="-0.0 0.036 0.0"/>
      <mass value="0.54"/>
      <inertia ixx="0.000381" ixy="-5.8e-05" ixz="-4.5e-07" iyy="0.00056" iyz="9.5e-07" izz="0.000444"/>
    </inertial>
  </link>
  <joint name="RL_thigh_joint" type="revolute">
    <origin rpy="0 0 0" xyz="0 0.062 0"/>
    <parent link="RL_hip_link"/>
    <child link="RL_thigh_link"/>
    <axis xyz="0 -1 0"/>
    <dynamics damping="0" friction="0"/>
    <limit effort="20" lower="-2.2689280275926285" upper="2.2689280275926285" velocity="10.6"/>
    <!-- <safety_controller k_velocity="10" k_position="15" soft_lower_limit="-2.0" soft_upper_limit="0.5" /> -->
  </joint>
  <link name="RL_thigh_link">
    <visual>
      <origin rpy="0 -1.5707963267948966 0" xyz="0 0 0"/>
      <geometry>
        <mesh filename="package://quadruped_description/meshes/mini_cheetah_thigh.obj" scale="1 1 1"/>
      </geometry>
      <material name="white_blue"/>
    </visual>
    <collision>
      <origin rpy="0 0 0" xyz="0 0 -0.11"/>
      <geometry>
        <box size="0.043 0.034 0.22"/>
      </geometry>
    </collision>
    <inertial>
      <origin rpy="0 0 0" xyz="0.0 0.016 -0.02"/>
      <mass value="0.634"/>
      <inertia ixx="0.0026182086666666662" ixy="0.0" ixz="0.0" iyy="0.0026548221666666664" iyz="0.0" izz="0.00015876416666666665"/>
    </inertial>
  </link>
  <joint name="RL_calf_joint" type="revolute">
    <origin rpy="0 0 0" xyz="0 0 -0.209"/>
    <parent link="RL_thigh_link"/>
    <child link="RL_calf_link"/>
    <axis xyz="0 -1 0"/>
    <dynamics damping="0" friction="0"/>
    <limit effort="20" lower="-2.9670597283903604" upper="2.9670597283903604" velocity="10.6"/>
    <!-- <safety_controller k_velocity="10" k_position="15" soft_lower_limit="-2.0" soft_upper_limit="0.5" /> -->
  </joint>
  <link name="RL_calf_link">
    <visual>
      <origin rpy="0 3.141592653589793 0" xyz="0 0 0"/>
      <geometry>
        <mesh filename="package://quadruped_description/meshes/mini_cheetah_calf.obj" scale="1 1 1"/>
      </geometry>
      <material name="white_blue"/>
    </visual>
    <collision>
      <origin rpy="0 0 0" xyz="0 0 -0.1"/>
      <geometry>
        <box size="0.016 0.016 0.2"/>
      </geometry>
    </collision>
    <inertial>
      <origin rpy="0 0 0" xyz="0.0 0.0 0.0"/>
      <mass value="0.064"/>
      <inertia ixx="0.0002146986666666667" ixy="0.0" ixz="0.0" iyy="0.0002146986666666667" iyz="0.0" izz="2.7306666666666666e-06"/>
    </inertial>
  </link>
  <joint name="RL_foot_fixed" type="fixed">
    <origin rpy="0 0 0" xyz="0 0 -0.18"/>
    <parent link="RL_calf_link"/>
    <child link="RL_foot_link"/>
  </joint>
  <link name="RL_foot_link">
    <visual>
      <origin rpy="0 0 0" xyz="0 0.0 0.0"/>
      <geometry>
        <sphere radius="0.025"/>
      </geometry>
      <material name="white_black"/>
    </visual>
    <collision>
      <origin rpy="0 0 0" xyz="0 0 0.0"/>
      <geometry>
        <sphere radius="0.025"/>
      </geometry>
    </collision>
    <inertial>
      <origin rpy="0 0 0" xyz="0.0 0.0 0"/>
      <mass value="0.15"/>
      <inertia ixx="4.2134999999999996e-05" ixy="0" ixz="0" iyy="4.2134999999999996e-05" iyz="0" izz="4.2134999999999996e-05"/>
    </inertial>
  </link>
</robot>
